Workbook

Sheet Checklist
C2: Agency Code | D2: 20673 | F2: Auditor Name | G2: Akshay
C3: Agency Name | D3: Jena Associates | F3: Audit Date | G3: 13/6/2026
C4: Agency Address | D4: B276 1st floor | F4: Collection Manager | G4: Parteek yadav
C5: Type of agency | D5: Collection & Repo Agency | F5: Agency Manager | G5: Parteek yadav
A7: Sr.No. | B7: Rating Category | C7: Short Segmentation | D7: Particular | E7: Final Score | F7: Compliance status (Yes / No) | G7: Observation | H7: Closing Meeting Comments | I7: Pending Status (Open/ Closed) | J7: Timelines for Non-Closure Point
A8: 1 | B8: Allocation Compliance | C8: Account to Collector Ratio – Not adequate | D8: Account to Collector Ratio – Stats need to be mentioned | E8: Only Observation Point | F8: Yes | G8: 2 CRE allocated for 289 cases in May 2026 for TW - Flows of Tata Capital | H8: NA
A9: 2 | B9: Allocation Compliance | C9: Not All cases allocated to agency CREs | D9: Check whether all the cases allocated to agency in being allocated to CRE | E9: =IF(F9="Yes",3,"0") | F9: Yes | G9: Yes the same is complied | H9: NA
A10: 3 | B10: Call recording | C10: Call recording facility not available | D10: Whether Call recording facility is available at the agency & is in working condition? Also, check whether all calls made to the customers via M collect App? | E10: =IF(F10="Yes",5,"0") | F10: Yes | G10: Agency using M Collect to Call Customer | H10: NA
A11: 4 | B11: Call recording | C11: Call recording Storage/Maintenance | D11: Whether call recording data is maintained as per policy? Also, check whether agency has done calling via M Collect App? Whether 100% call recording is done and maintained by the agency & retrieved all sample calls provided during audit?(Dialler + M-Collect) | E11: =IF(F11="Yes",4,"0") | F11: No | G11: Sample Calls could not be retrieved at the time of the audit | H11: Manager will provide the call recording samples
A12: 5 | B12: TCOC | C12: Telephone Etiquette not followed | D12: Whether telephone etiquette is followed in calls? Any Non Compliance as per code of conduct & TCOC also if any Misbehaviour observed in calls to be noted. | E12: =IF(F12="Yes",3,"0") | F12: No | G12: No Calling Sample available for Verification | H12: Manager will provide the call recording samples
A13: 6 | B13: TCOC | C13: Pseudo names | D13: Check whether tele callers using pseudo names? | E13: =IF(F13="Yes",2,"0") | F13: No | G13: No Calling Sample available for Verification | H13: Manager will provide the call recording samples
A14: 7 | B14: TCOC | C14: TCL Posters | D14: Whether the Code of Conduct posters/ Collections Dos and Don'ts/ any other communication displayed in the offices? | E14: =IF(F14="Yes",2,"0") | F14: Yes | G14: Yes the same is complied | H14: NA
A15: 8 | B15: TCOC | C15: TCOC training not given by TCL Collection Manager | D15: Whether all agents are trained on the code of conduct and are well dressed while on field ? (Need to check the acknowledgement of the training given by CM) Authorisation Letter - Signed by Collection Manager must required with CREs details | E15: =IF(F15="Yes",2,"0") | F15: No | G15: Signature of attendees not available on the Training Letter | H15: Agency will take care in the future
A16: 9 | B16: TCOC | C16: COC declaration from all Agents must be stored | D16: Collection agency need to be taken declaration on code of conduct from all CRE's and this must be stored. | E16: =IF(F16="Yes",2,"0") | F16: Yes | G16: Yes the same is complied | H16: NA
A17: 10 | B17: Cash Collection | C17: Cash Collection limit of 2 Lacs breached | D17: - Whether agency CRE has collected cash more than Rs. 1.99 lacs at any point in time during the Emi Months? (Sum of collected amount to be checked as per Loan No./customer name) - PAN at the time of collecting cash more than Rs. 49k | E17: =IF(F17="Yes",2,"0") | F17: Yes | G17: Yes the same is complied | H17: NA
A18: 11 | B18: Cash Collection | C18: Deposit delay seen during sample check | D18: Whether the agency ensures that collections deposited within the TAT?Is there any instance of delayed deposition (More than 2 Days), If so, how many such instances are there | E18: =IF(F18="Yes",5,"0") | F18: Yes | G18: Yes the same is complied | H18: NA
A19: 12 | B19: Cash Collection | C19: Unauthorized transaction in customer account | D19: Unauthorized transaction in customer account, For Example-Payment done on behalf of Customer or accepting payment in CRE's personal account (GPay, Paytm or any other wallet/bank account). | E19: =IF(F19="Yes",3,"0") | F19: Yes | G19: Yes the same is complied | H19: NA
A20: 13 | B20: Cash Collection | C20: Multiple Receipt with Multiple Pin Code | D20: M-Collect Receipts issuance data to be reviewed, in case any CRE issuing unrealistic no. of receipts, reasons to be check | E20: Only Observation Point | F20: No | G20: Unrealistic no. of receipts in a day issued by the CRE/Agency (Refer to annexure) | H20: Agency will take care in the future
A21: 14 | B21: Cash Collection | C21: Receipts Issuance in Non Working Hours | D21: Any instance where M-Collect Receipt has been issued in Non-Working Hours | E21: =IF(F21="Yes",3,"0") | F21: No | G21: M-Collect Receipt has been issued in Non-Working Hours (Refer to annexure) | H21: As per agency customer available on same time
A22: 15 | B22: Cash Collection | C22: Receipts issuance by other Agency | D22: Any Receipts issued by the agency which is not in allocation Or CM/Off role are issuing receipts instead of same agency | E22: Only Observation Point | F22: No | G22: 1) Receipts issued by the agency which is not in allocation (TCFTW0538000012532285 - 15-03-2026 - 20673009 - Case allocated to 19025) 2) Agency/CM/Offrole are issuing receipts instead of same agency (2603514449, 2604515576 - Receipt issued by 20551) | H22: Agency will discuss with Manager
A23: 16 | B23: Cash Collection | C23: Customer payment not deposited to agency or TCL | D23: Any instances where the CRE collected the money from the customer but the same was not deposited In customer account/not deposited to agency/not deposited in TCL? | E23: =IF(F23="Yes",3,"0") | F23: Yes | G23: Yes the same is complied | H23: NA
A24: 17 | B24: Data Security | C24: Agency system has no restrictions hence data may fall into wrong hands | D24: Whether agency has restricted access of Desktop / Laptops/ Emails are enabled? Check whether agency do not have access of USB/Floppy/CD drives/Google Drive/Cloud storage/share drive/WhatsApp/any data sharing application for data transfer? | E24: =IF(F24="Yes",4,"0") | F24: Yes | G24: Yes the same is complied | H24: NA
A25: 18 | B25: Data Security | C25: Allocation files were not password protected | D25: Whether data shared through mail are password protected / appropriate security measures are adopted by agency? | E25: =IF(F25="Yes",2,"0") | F25: Yes | G25: Yes the same is complied | H25: NA
A26: 19 | B26: Data Security | C26: Data is being shared on unregistered email ids | D26: Whether any mail containing financial institution's data sent to third party / unregistered mail Ids / unauthorized sharing? Customer Call/Chat on unauthorized channels like what's ap/Facebook or any other unauthorized mode of communication? In case agencies using secondary mail id, it must be documented with TCL team. | E26: =IF(F26="Yes",3,"0") | F26: No | G26: Communication/Data shared through mail by the agency to unauthorised Email ID (Email : associatesjena@gmail.com) | H26: Agency will take care in the future
A27: 20 | B27: Data Security | C27: Data purging is not being done – Old allocation files were available in agency's system | D27: Whether agency has purged data as per policy? | E27: =IF(F27="Yes",3,"0") | F27: No | G27: Data is not purged from system as per the TCL process (maintained Since December 2025) | H27: Agency will purge the old data as per policy
A28: 21 | B28: Data Security | C28: Data Retention | D28: Whether data has been retained at the agency's system and Email ID as per policy (T+3 months)? | E28: =IF(F28="Yes",2,"0") | F28: Yes | G28: Yes the same is complied | H28: NA
A29: 22 | B29: Data Security | C29: Agency system has no restrictions hence data may fall into wrong hands | D29: Check whether agency do not have access of any internal access tool like SFDC/DMS/Any other tool? | E29: =IF(F29="Yes",2,"0") | F29: Yes | G29: Yes the same is complied | H29: NA
A30: 23 | B30: Data Security | C30: No exclusive system provided to TCL portfolio | D30: Whether separate/exclusive system, Place/work Station, Email ID and Manpower is provided? | E30: =IF(F30="Yes",3,"0") | F30: No | G30: Common mail account and system is used for TCL and other Banks/NBFCs (Bajaj, IDFC, Jana Bank etc) | H30: Agency will maintained separate mail and system for TCL
A31: 24 | B31: Infra and others | C31: Current address is not updated to TCL | D31: Whether agency has updated address & other details in company records and, In case agency providing services in multiple locations to TCL Collection then it must be documented with TCL team. | E31: =IF(F31="Yes",1,"0") | F31: No | G31: Operating address of agency is not updated in the TCL records. | H31: Agency will discuss with the collection manager
A32: 25 | B32: Infra and others | C32: Not cooperated by agency during audit | D32: Whether full cooperation/complete & timely data was received from agency for completing audit? | E32: =IF(F32="Yes",1,"0") | F32: Yes | G32: Yes the same is complied | H32: NA
A33: 26 | B33: Infra and others | C33: Vendor code not created | D33: Whether allocation for Collection cases given to the agency post vendor code creation only? | E33: =IF(F33="Yes",1,"0") | F33: Yes | G33: Yes the same is complied | H33: NA
A34: 27 | B34: Infra and others | C34: Tata capital's name being used in agency office | D34: Has the agency made any reference to company's name on the his's name board & e-mail ? | E34: =IF(F34="Yes",1,"0") | F34: Yes | G34: Yes the same is complied | H34: NA
A35: 28 | B35: Identity cards | C35: All CREs have valid ID Cards of TCL | D35: Whether all active CREs working for TCL portfolio having Digital ID Cards with them? Also, check whether any executive using unauthorized ID card while on field? | E35: =IF(F35="Yes",3,"0") | F35: Yes | G35: Yes the same is complied | H35: NA
A36: 29 | B36: Identity cards | C36: If assigned CRE resigned/terminated it is not communicated to TCL | D36: In case of resignation / termination of any executive whether it is communicated within TAT of 24 hours; (M-collect ID should be deactivated ) | E36: =IF(F36="Yes",2,"0") | F36: Yes | G36: No such cases have been observed | H36: NA
A37: 30 | B37: Identity cards | C37: Not all CREs have M Collect ID's | D37: Whether all active CRE has M-collect ID in system? (M-collect should be active) Is there M-collect ID of any CRE being used by another CRE? | E37: =IF(F37="Yes",4,"0") | F37: Yes | G37: Yes the same is complied | H37: NA
A38: 31 | B38: Identity cards | C38: PV report not available | D38: Whether all agency executives, backends, Supervisor,Proprieter, CRE's Police verification are vetted & no negative Police verification CRE's are working at the agency? | E38: =IF(F38="Yes",3,"0") | F38: Yes | G38: Yes the same is complied | H38: NA
A39: 32 | B39: Record Management | C39: Collection Deposit sheets not maintained by agency office | D39: Whether Collection deposit slips maintain by agency? | E39: Only Observation Point | F39: Yes | G39: No such case has been observed | H39: NA
A40: 33 | B40: Record Management | C40: Feedback file not shared on daily basis | D40: Whether all allocated cases feedback are getting reviewed by collection manager every month? | E40: =IF(F40="Yes",1,"0") | F40: No | G40: Feedback file not shared on daily basis | H40: Agency will take care in the future
A41: 34 | B41: Record Management | C41: TCOC training not recorded | D41: Whether Training tracker in the Blue Book has been properly filled with all necessary fields and maintained at agency? | E41: =IF(F41="Yes",2,"0") | F41: No | G41: Complete/correct details are not mentioned on the Training tracker (Training Date not matching with Training letter - April and May 2026) | H41: Agency will take care in the future
A42: 35 | B42: Record Management | C42: Trails are not being updated at 100% | D42: Whether 100% of trails uploaded by agency for cases allocated to them? All trails are uploaded should be quality trails. | E42: =IF(F42="Yes",2,"0") | F42: No | G42: Trails for certain cases have not been uploaded by the agency (March 2026 - TCFTW0538000011789283, TCFTW0538000013136158; May 2026 - TCFTW0538000012823685, TCFTW0538000013828714) | H42: Agency will discuss with Manager
...

Sheet Score Parameters
A1: S. No. | B1: Particulars | C1: Key Points | D1: Weightage | E1: Actual | F1: Percentage
A2: 1 | B2: Allocation Compliance | C2: =COUNTIF(Checklist!$B$7:$B$58,B2) | D2: 3 | E2: =SUMIF(Checklist!$B$7:$B$58,'Score Parameters'!B2,Checklist!$E$7:$E$58) | F2: =IFERROR(E2/D2,"-")
A3: 2 | B3: Call recording | C3: =COUNTIF(Checklist!$B$7:$B$58,B3) | D3: 9 | E3: =SUMIF(Checklist!$B$7:$B$58,'Score Parameters'!B3,Checklist!$E$7:$E$58) | F3: =IFERROR(E3/D3,"-")
A4: 3 | B4: TCOC | C4: =COUNTIF(Checklist!$B$7:$B$58,B4) | D4: 11 | E4: =SUMIF(Checklist!$B$7:$B$58,'Score Parameters'!B4,Checklist!$E$7:$E$58) | F4: =IFERROR(E4/D4,"-")
A5: 4 | B5: Cash Collection | C5: =COUNTIF(Checklist!$B$7:$B$58,B5) | D5: 16 | E5: =SUMIF(Checklist!$B$7:$B$58,'Score Parameters'!B5,Checklist!$E$7:$E$58) | F5: =IFERROR(E5/D5,"-")
A6: 5 | B6: Data Security | C6: =COUNTIF(Checklist!$B$7:$B$58,B6) | D6: 19 | E6: =SUMIF(Checklist!$B$7:$B$58,'Score Parameters'!B6,Checklist!$E$7:$E$58) | F6: =IFERROR(E6/D6,"-")
A7: 6 | B7: Infra and others | C7: =COUNTIF(Checklist!$B$7:$B$58,B7) | D7: 4 | E7: =SUMIF(Checklist!$B$7:$B$58,'Score Parameters'!B7,Checklist!$E$7:$E$58) | F7: =IFERROR(E7/D7,"-")
A8: 7 | B8: Identity cards | C8: =COUNTIF(Checklist!$B$7:$B$58,B8) | D8: 12 | E8: =SUMIF(Checklist!$B$7:$B$58,'Score Parameters'!B8,Checklist!$E$7:$E$58) | F8: =IFERROR(E8/D8,"-")
A9: 8 | B9: Record Management | C9: =COUNTIF(Checklist!$B$7:$B$58,B9) | D9: 23 | E9: =SUMIF(Checklist!$B$7:$B$58,'Score Parameters'!B9,Checklist!$E$7:$E$58) | F9: =IFERROR(E9/D9,"-")
A10: 9 | B10: Settlement Compliance | C10: =COUNTIF(Checklist!$B$7:$B$58,B10) | D10: 3 | E10: =SUMIF(Checklist!$B$7:$B$58,'Score Parameters'!B10,Checklist!$E$7:$E$58) | F10: =IFERROR(E10/D10,"-")
A11: 10 | B11: Miscellaneous | C11: =COUNTIF(Checklist!$B$7:$B$58,B11) | D11: 0 | E11: =SUMIF(Checklist!$B$7:$B$58,'Score Parameters'!B11,Checklist!$E$7:$E$58) | F11: =IFERROR(E11/D11,"-")
B12: Total | C12: =SUM(C2:C11) | D12: =SUM(D2:D11) | E12: =SUM(E2:E11) | F12: =E12/D12
A13: FINAL RATING | F13: {=_xlfn.IFS(F12>=80%,B16,F12>=70%,B17,F12>=60%,B18,F12>=50%,B19,F12<=49%,B20)}
B15: Rating | C15: Scoring Segmentation
B16: A | C16: >=80
B17: B | C17: >=70 and <=79
B18: C | C18: >=60 and <=69
B19: D | C19: >=50 and <=59
B20: E | C20: <=49
