Workbook

Sheet Rating
B2: YES Bank Collection Agency Audit
B5: Version | C5: Ver.2
B6: Agency Name | D6: Agency Location | F6: Agency Address
B7: Audit Date | D7: Audit Period | F7: Audit Firm Name | G7: Kumar Gaurav Agarwal & Company
B8: CM Name | D8: CCL Name | F8: Auditor Name/Contact#
B9: CM Employee ID | D9: CCL Employee ID | E9: NA
B10: Products for which agency does collections | C10: Retail Collection | D10: Agency person with whom the discussion were held
B13: Agency Audit Score
B14: Final Audit Score | C14: Actual | D14: Weightage | E14: Percantage | F14: Grade
B16: Blue book,Receipt Book and ID Card | C16: =Agency!J29 -> 30 | D16: 30 | E16: =C16/D16 -> 1
B17: Allocation,Call Recording ,Target Letter & Vendor Performance Report | C17: =Agency!J47 -> 30 | D17: 30 | E17: =C17/D17 -> 1
B18: System Security | C18: =Agency!J58 -> 30 | D18: 30 | E18: =C18/D18 -> 1
B19: Insurance, Shop Establishment Certificate and Code of conduct | C19: =Agency!J61 -> 5 | D19: 5 | E19: =C19/D19 -> 1
B20: Infrastructure & Other | C20: =Agency!J69 -> 5 | D20: 5 | E20: =C20/D20 -> 1
B21: Total Score | C21: =SUM(C16:C20) -> 100 | D21: =SUM(D16:D20) -> 100 | E21: =C21/D21 -> 1 | F21: =IF(ROUNDUP(E21,2)<60%,"C",IF(ROUNDUP(E21,2)<70%,"C+",IF(ROUNDUP(E21,2)<80%,"B",IF(ROUNDUP(E21,2)<90%,"B+",IF(ROUNDUP(E21,2)<100%,"A","A+"))))) -> A+
B22: Final Rating on Agency Audit | C22: =VLOOKUP($F$21,$C$27:$D$33,2,FALSE) -> Excellent
B26: Scoring and Grade Matrix
B27: Score | C27: Grade | D27: Performance
B28: 100 | C28: A+ | D28: Excellent
B29: 90-99 | C29: A | D29: Very Good
B30: 80-89 | C30: B+ | D30: Good
B31: 70-79 | C31: B | D31: Satisfactory
B32: 60-69 | C32: C+ | D32: Unsatisfactory
B33: 59 and Below | C33: C | D33: Poor

Sheet Agency
A1: Sr. No. | B1: Main category | C1: Check points Category | D1: Risk Level | E1: Details to be checked | F1: Points to be checked | G1: Scoring Parameter | H1: Complied (Yes/No) | I1: No. of Errors | J1: Score | K1: Clarification | L1: Observations | M1: Revert from the CM | N1: Revert from the Auditor | O1: Annx.
A2: 1 | B2: AGREEMENT COPY | C2: Agreement & rate annexure | D2: High | E2: Whether the vendor agreement and the latest rate annexures maintained at the agency? Whether the Code of Conduct poster is displayed at the agency? | F2: 1) Agreement has to be signed by both the parties i.e Bank and Agency. | G2: Done : 10 else : 0 | H2: Yes | I2: NA | J2: =IF(H2="NA","NA",IF(H2="Yes",10,0)) -> 10 | K2: Detailed observations needs to be updated here. And details of missing documents or any other pendency should be updated in the Annexure sheet | L2: Yes, Compete vendor agreement is maintained at the agency
A3: 2 | B3: AGREEMENT COPY | C3: Agreement & rate annexure | D3: High | E3: Whether the vendor agreement and the latest rate annexures maintained at the agency? Whether the Code of Conduct poster is displayed at the agency? | F3: 2) If supplementary agreement the scope of work for Retails Collections needs to there. | G3: Done : 10 else : 0 | H3: Yes | I3: NA | J3: =IF(H3="NA","NA",IF(H3="Yes",10,0)) -> 10 | K3: Detailed observations needs to be updated here. And details of missing documents or any other pendency should be updated in the Annexure sheet | L3: Yes, Compete agreement is maintained at the agency
A4: 3 | B4: AGREEMENT COPY | C4: Agreement & rate annexure | D4: High | E4: Whether the vendor agreement and the latest rate annexures maintained at the agency? Whether the Code of Conduct poster is displayed at the agency? | F4: 3) Latest rate annexure | G4: Done : 10 else : 0 | H4: Yes | I4: NA | J4: =IF(H4="NA","NA",IF(H4="Yes",10,0)) -> 10 | K4: Detailed observations needs to be updated here. And details of missing documents or any other pendency should be updated in the Annexure sheet | L4: Yes, latest rate annexures maintained at the agency
A5: 4 | B5: AGREEMENT COPY | C5: Agreement & rate annexure | D5: High | E5: Whether the vendor agreement and the latest rate annexures maintained at the agency? Whether the Code of Conduct poster is displayed at the agency? | F5: 4) COC should be signed and displayed. | G5: Done : 10 else : 0 | H5: Yes | I5: NA | J5: =IF(H5="NA","NA",IF(H5="Yes",10,0)) -> 10 | K5: Detailed observations needs to be updated here. And details of missing documents or any other pendency should be updated in the Annexure sheet | L5: Yes, Code of Conduct poster is displayed at the agency
A6: 5 | B6: BLUEBOOK | C6: Hygiene | D6: High | E6: Whether blue book formats are filled completely & correctly by the agencies . | F6: 1) Code of Conduct page should be signed by agency's owner. | G6: Done: 10 else 2 for each such case | H6: Yes | I6: NA | J6: =IF(H6="NA","NA",IF(H6="Yes",10,IF(I6=1,8,IF(I6=2,6,IF(I6=3,4,IF(I6=4,2,IF(I6>=4,0))))))) -> 10 | L6: Blue book formats are filled completely/correctly by the agency
A7: 6 | B7: BLUEBOOK | C7: Hygiene | D7: High | E7: Whether blue book formats are filled completely & correctly by the agencies . | F7: 2) Declaration cum undertaking page owners/CP signature should be filled up in blue book. | G7: Done: 10 else 2 for each such case | H7: Yes | I7: NA | J7: =IF(H7="NA","NA",IF(H7="Yes",10,IF(I7=1,8,IF(I7=2,6,IF(I7=3,4,IF(I7=4,2,IF(I7>=4,0))))))) -> 10 | L7: Blue book formats are filled completely/correctly by the agency
A8: 7 | B8: BLUEBOOK | C8: Hygiene | D8: High | E8: Whether blue book formats are filled completely & correctly by the agencies . | F8: 3)Data purging declaration should be filled up completely in blue book. | G8: Done: 10 else 2 for each such case | H8: Yes | I8: NA | J8: =IF(H8="NA","NA",IF(H8="Yes",10,IF(I8=1,8,IF(I8=2,6,IF(I8=3,4,IF(I8=4,2,IF(I8>=4,0))))))) -> 10 | L8: Blue book formats are filled completely/correctly by the agency
A9: 8 | B9: BLUEBOOK | C9: Hygiene | D9: High | E9: Whether blue book formats are filled completely & correctly by the agencies . | F9: 4)Computer Declaration in Infrastructure details should be filled properly. | G9: Done: 10 else 2 for each such case | H9: Yes | I9: NA | J9: =IF(H9="NA","NA",IF(H9="Yes",10,IF(I9=1,8,IF(I9=2,6,IF(I9=3,4,IF(I9=4,2,IF(I9>=4,0))))))) -> 10 | L9: Blue book formats are filled completely/correctly by the agency
A10: 9 | B10: BLUEBOOK | C10: Hygiene | D10: High | E10: Whether blue book formats are filled completely & correctly by the agencies . | F10: 5)Telephone Declaration in Infrastructure details should be filled up properly. | G10: Done: 10 else 2 for each such case | H10: Yes | I10: NA | J10: =IF(H10="NA","NA",IF(H10="Yes",10,IF(I10=1,8,IF(I10=2,6,IF(I10=3,4,IF(I10=4,2,IF(I10>=4,0))))))) -> 10 | L10: Blue book formats are filled completely/correctly by the agency
A11: 10 | B11: BLUEBOOK | C11: Hygiene | D11: High | E11: Whether blue book formats are filled completely & correctly by the agencies . | F11: 6) Agency manpower register should be filled up properly and completely and ID card details should be matched with bank record. | G11: Done: 10 else 2 for each such case | H11: Yes | I11: NA | J11: =IF(H11="NA","NA",IF(H11="Yes",10,IF(I11=1,8,IF(I11=2,6,IF(I11=3,4,IF(I11=4,2,IF(I11>=4,0))))))) -> 10 | L11: Blue book formats are filled completely/correctly by the agency
A12: 11 | B12: BLUEBOOK | C12: Hygiene | D12: High | E12: Whether blue book formats are filled completely & correctly by the agencies . | F12: 7) Receipt book issuance register should be filled up properly and completely and should be matched with bank record. | G12: Done: 10 else 2 for each such case | H12: NA | I12: NA | J12: =IF(H12="NA","NA",IF(H12="Yes",10,IF(I12=1,8,IF(I12=2,6,IF(I12=3,4,IF(I12=4,2,IF(I12>=4,0))))))) -> NA | L12: Na as no physical receipt books are issued to the agency for the Audit period
A13: 12 | B13: BLUEBOOK | C13: Hygiene | D13: High | E13: Whether blue book formats are filled completely & correctly by the agencies . | F13: 8) Agency training tracker should be filled up by CP/RCM if training has been provided. | G13: Done: 10 else 2 for each such case | H13: Yes | I13: NA | J13: =IF(H13="NA","NA",IF(H13="Yes",10,IF(I13=1,8,IF(I13=2,6,IF(I13=3,4,IF(I13=4,2,IF(I13>=4,0))))))) -> 10 | L13: Blue book formats are filled completely/correctly by the agency
A14: 13 | B14: BLUEBOOK | C14: Hygiene | D14: High | E14: Whether blue book formats are filled completely & correctly by the agencies . | F14: 9) Billing tracker should be filled up completely in Blue book. | G14: Done: 10 else 2 for each such case | H14: Yes | I14: NA | J14: =IF(H14="NA","NA",IF(H14="Yes",10,IF(I14=1,8,IF(I14=2,6,IF(I14=3,4,IF(I14=4,2,IF(I14>=4,0))))))) -> 10 | L14: Blue book formats are filled completely/correctly by the agency
A15: 14 | B15: BLUEBOOK | C15: Hygiene | D15: High | E15: Whether blue book formats are filled completely & correctly by the agencies . | F15: 10) Repokit tracker should be filled up and matched with bank record applicable only for repo agency. | G15: Done: 10 else 2 for each such case | H15: NA | I15: NA | J15: =IF(H15="NA","NA",IF(H15="Yes",10,IF(I15=1,8,IF(I15=2,6,IF(I15=3,4,IF(I15=4,2,IF(I15>=4,0))))))) -> NA | L15: Na as no Repokit are issued to the agency for the Audit period
A16: 15 | B16: BLUEBOOK | C16: Visitor Register | D16: Low | E16: Whether agency maintains visitor register in blue book at their office ? Also, check if Collection Partner (CP) / Regional Collection Manager (RCM) visiting the agency signs the visiting register maintained at the agency? | F16: 1) Copy of visitor register needs to be taken during audit. | G16: Done : 10 else : 0 | H16: Yes | I16: NA | J16: =IF(H16="NA","NA",IF(H16="Yes",10,0)) -> 10 | L16: Blue book formats are filled completely/correctly by the agency
A17: 16 | B17: BLUEBOOK | C17: Register | D17: Medium | E17: 1. Whether physical receipt books are issued to the agency. 2. Whether agency has maintained and submitted the receipt reconciliation to the Bank? | F17: 1) Please cross tally physical receipt book register maintained at agency with Central Team data? | G17: Done : 10 else : reduce 5 for each error | H17: NA | I17: NA | J17: =IF(H17="NA","NA",IF(H17="Yes",10,IF(I17=1,5,0))) -> NA | L17: Na as no physical receipt books are issued to the agency for the Audit period
A18: 17 | B18: BLUEBOOK | C18: Register | D18: Medium | E18: 1. Whether physical receipt books are issued to the agency. 2. Whether agency has maintained and submitted the receipt reconciliation to the Bank? | F18: 2) Please check agency has maintained physical receipt book reconciliation statement if agency has used physical receipt book.Also cross check whrther agency has sent reconcillation statement to bank on monthly basis via mail. | G18: Done : 10 else : reduce 5 for each error | H18: NA | I18: NA | J18: =IF(H18="NA","NA",IF(H18="Yes",10,IF(I18=1,5,0))) -> NA | L18: Na as no physical receipt books are issued to the agency for the Audit period
A19: 18 | B19: RECEIPT BOOK | C19: Register | D19: Medium | E19: 1.Whether cash collected is deposited in Time? | F19: Please check receipt date and deposition date mentioned in receipt reconcillation MIS and also cross check batch id/hand off sheet/ CAPS Deposition Memo | G19: Done: 10 else: -2 for each case of deposition >= 2 days (without any justification) Critical: -10 if delay> 5days or any case of non deposition | H19: NA | I19: NA | J19: =IF(H19="NA","NA",IF(H19="Yes",10,IF(H19="Critical",-10,IF(I19=1,-2,IF(I19=2,-4,IF(I19=3,-6,IF(I19=4,-8,-10))))))) -> NA | K19: Agencies / In-house team should deposit the collected payments in designated our Bank branches within 24 hours of collection. | L19: NA as, During the audit review for the current quarter, it has been verified that no cash collection has been carried out by the designated agency
A20: 19 | B20: RECEIPT BOOK | C20: Issuance | D20: High | E20: 1.Please comment about the process of filling in the receipts (completely and correctly and without cuttings/alterations/ over writing on the receipts). 2.Do all cancelled receipts have all Four copies with the branch (Also check for hologram in cancelled receipts)? 3.Hologram needs to be tamperred on all cancelled and expired receipts. 4.Does the branch have FIR copies,indemnity bond and newspaper advertisement cutout for lost receipts ? 5.Whether the agencies managed by the Collection Partner (CP) have returned the expired/used receipt books as per process. Also applicable for the in-house books used by the Collection Partner (CP) 6.Whether all unused receipt books are in safe custody of agency's authorized person or not? | F20: 1.Please comment about the process of filling in the receipts (completely and correctly and without cuttings/alterations/ over writing on the receipts). | G20: Done : 10 else : 0 | H20: NA | I20: NA | J20: =IF(H20="NA","NA",IF(H20="Yes",10,0)) -> NA | L20: NA as, During the audit review for the current quarter, it has been verified that no cash collection has been carried out by the designated agency
A21: 20 | B21: RECEIPT BOOK | C21: Issuance | D21: High | E21: 1.Please comment about the process of filling in the receipts (completely and correctly and without cuttings/alterations/ over writing on the receipts). 2.Do all cancelled receipts have all Four copies with the branch (Also check for hologram in cancelled receipts)? 3.Hologram needs to be tamperred on all cancelled and expired receipts. 4.Does the branch have FIR copies,indemnity bond and newspaper advertisement cutout for lost receipts ? 5.Whether the agencies managed by the Collection Partner (CP) have returned the expired/used receipt books as per process. Also applicable for the in-house books used by the Collection Partner (CP) 6.Whether all unused receipt books are in safe custody of agency's authorized person or not? | F21: 2.Do all cancelled receipts have all Four copies with the branch (Also check for hologram in cancelled receipts)? | G21: Done : 10 else : 0 | H21: NA | I21: NA | J21: =IF(H21="NA","NA",IF(H21="Yes",10,0)) -> NA | L21: NA as, During the audit review for the current quarter, it has been verified that no cash collection has been carried out by the designated agency
A22: 21 | B22: RECEIPT BOOK | C22: Issuance | D22: High | E22: 1.Please comment about the process of filling in the receipts (completely and correctly and without cuttings/alterations/ over writing on the receipts). 2.Do all cancelled receipts have all Four copies with the branch (Also check for hologram in cancelled receipts)? 3.Hologram needs to be tamperred on all cancelled and expired receipts. 4.Does the branch have FIR copies,indemnity bond and newspaper advertisement cutout for lost receipts ? 5.Whether the agencies managed by the Collection Partner (CP) have returned the expired/used receipt books as per process. Also applicable for the in-house books used by the Collection Partner (CP) 6.Whether all unused receipt books are in safe custody of agency's authorized person or not? | F22: 3.Hologram needs to be tamperred on all cancelled and expired receipts. | G22: Done : 10 else : 0 | H22: NA | I22: NA | J22: =IF(H22="NA","NA",IF(H22="Yes",10,0)) -> NA | L22: NA as, During the audit review for the current quarter, it has been verified that no cash collection has been carried out by the designated agency
A23: 22 | B23: RECEIPT BOOK | C23: Issuance | D23: High | E23: 1.Please comment about the process of filling in the receipts (completely and correctly and without cuttings/alterations/ over writing on the receipts). 2.Do all cancelled receipts have all Four copies with the branch (Also check for hologram in cancelled receipts)? 3.Hologram needs to be tamperred on all cancelled and expired receipts. 4.Does the branch have FIR copies,indemnity bond and newspaper advertisement cutout for lost receipts ? 5.Whether the agencies managed by the Collection Partner (CP) have returned the expired/used receipt books as per process. Also applicable for the in-house books used by the Collection Partner (CP) 6.Whether all unused receipt books are in safe custody of agency's authorized person or not? | F23: 4.Does the branch have FIR copies,indemnity bond and newspaper advertisement cutout for lost receipts ? | G23: Done : 10 else : 0 | H23: NA | I23: NA | J23: =IF(H23="NA","NA",IF(H23="Yes",10,0)) -> NA | L23: NA as, During the audit review for the current quarter, it has been verified that no cash collection has been carried out by the designated agency
A24: 23 | B24: RECEIPT BOOK | C24: Issuance | D24: High | E24: 1.Please comment about the process of filling in the receipts (completely and correctly and without cuttings/alterations/ over writing on the receipts). 2.Do all cancelled receipts have all Four copies with the branch (Also check for hologram in cancelled receipts)? 3.Hologram needs to be tamperred on all cancelled and expired receipts. 4.Does the branch have FIR copies,indemnity bond and newspaper advertisement cutout for lost receipts ? 5.Whether the agencies managed by the Collection Partner (CP) have returned the expired/used receipt books as per process. Also applicable for the in-house books used by the Collection Partner (CP) 6.Whether all unused receipt books are in safe custody of agency's authorized person or not? | F24: 5.Whether the agencies managed by the Collection Partner (CP) have returned the expired/used receipt books as per process. Also applicable for the in-house books used by the Collection Partner (CP) | G24: Done : 10 else : 0 | H24: NA | I24: NA | J24: =IF(H24="NA","NA",IF(H24="Yes",10,0)) -> NA | L24: NA as, During the audit review for the current quarter, it has been verified that no cash collection has been carried out by the designated agency
A25: 24 | B25: RECEIPT BOOK | C25: Issuance | D25: High | E25: 1.Please comment about the process of filling in the receipts (completely and correctly and without cuttings/alterations/ over writing on the receipts). 2.Do all cancelled receipts have all Four copies with the branch (Also check for hologram in cancelled receipts)? 3.Hologram needs to be tamperred on all cancelled and expired receipts. 4.Does the branch have FIR copies,indemnity bond and newspaper advertisement cutout for lost receipts ? 5.Whether the agencies managed by the Collection Partner (CP) have returned the expired/used receipt books as per process. Also applicable for the in-house books used by the Collection Partner (CP) 6.Whether all unused receipt books are in safe custody of agency's authorized person or not? | F25: 6.Whether all unused receipt books are in safe custody of agency's authorized person or not? | G25: Done : 10 else : 0 | H25: NA | I25: NA | J25: =IF(H25="NA","NA",IF(H25="Yes",10,0)) -> NA | L25: NA as, During the audit review for the current quarter, it has been verified that no cash collection has been carried out by the designated agency
A26: 25 | B26: ID CARD | C26: ID card and Manpower | D26: High | E26: Whether all the Field Executives are DRA certified and have valid digital ID card issued by Yes Bank? | F26: 1)ID card need to be generated live during audit visit and also take screenshots of all ID card isssued by bank. | G26: Done: 10 else: -2 for each case of non compliance | H26: Yes | I26: NA | J26: =IF(H26="NA","NA",IF(H26="Yes",10,IF(I26=1,-2,IF(I26=2,-4,IF(I26=3,-6,IF(I26=4,-8,-10)))))) -> 10 | L26: Yes, All Field Executives are DRA certified and hold valid digital ID cards issued by Yes Bank as per policy requirements.
A27: 26 | B27: DRA | C27: Telecaller | D27: High | E27: Whether all Callers working in agency are DRA certified? | F27: Please take screenshots of all DRA certificate of Telecaller working for YBL. | G27: Done: 10 else: -2 for each case of non compliance | H27: Yes | I27: NA | J27: =IF(H27="NA","NA",IF(H27="Yes",10,IF(I27=1,-2,IF(I27=2,-4,IF(I27=3,-6,IF(I27=4,-8,-10)))))) -> 10 | L27: Yes, All Callers employed by the agency are DRA certified in accordance with regulatory and institutional requirements.
A28: 27 | B28: ID CARD | C28: ID card and Manpower | D28: High | E28: Whether all ID cards where executives have been resigned/terminated are submitted to CP/Central Processing Team and same has been updated in ID card tracker of bluebook or not? | F28: Whether all ID cards where executives have been resigned/terminated are submitted to CP/Central Processing Team and same has been updated in ID card tracker of bluebook or not? | G28: Done: 10 else 2 for each such case | H28: NA | I28: NA | J28: =IF(H28="NA","NA",IF(H28="Yes",10,IF(I28=1,8,IF(I28=2,6,IF(I28=3,4,IF(I28=4,2,0)))))) -> NA | L28: NA as no Such case was observed for the audit period
A29: A | E29: Sub-Total | J29: =(SUM(J2:J28)/(COUNT(J2:J28)*10)*30) -> 30
A30: 28 | B30: ALLOCATION | C30: Y CAPS | D30: Medium | E30: Whether agency is using Y CAPS to download allocation and if they are able to download allocation cases on Y CAPS? Whether the allocation downloaded by CAPS is matching with the allocation sent by the Bank? | F30: 1) Auditor should do live checking of Y CAPS Allocation download at the time of audit. | G30: Done: 10 else: -2 for each case of non compliance | H30: Yes | I30: NA | J30: =IF(H30="NA","NA",IF(H30="Yes",10,IF(I30=1,-2,IF(I30=2,-4,IF(I30=3,-6,IF(I30=4,-8,-10)))))) -> 10 | L30: Yes, the same has been compiled by the agency as per Bank Process
A31: 29 | B31: ALLOCATION | C31: Y CAPS | D31: Medium | E31: Whether agency is using Y CAPS to download allocation and if they are able to download allocation cases on Y CAPS? Whether the allocation downloaded by CAPS is matching with the allocation sent by the Bank? | F31: 2) Cross tally allocation downloaded on caps with allocation available in system as well as allocation provided by Central team for audit purpose. | G31: Done: 10 else: -2 for each case of non compliance | H31: Yes | I31: NA | J31: =IF(H31="NA","NA",IF(H31="Yes",10,IF(I31=1,-2,IF(I31=2,-4,IF(I31=3,-6,IF(I31=4,-8,-10)))))) -> 10 | L31: Yes, the same has been compiled by the agency as per Bank Process
A32: 30 | B32: ALLOCATION | C32: Allocation mappin with ID Card | D32: High | E32: Whether All allocations is allocated to Valid ID card holder person only? | F32: Please check allocation file and cross check whether all cases have been mapped against valid ID card holder.Details should be captured if any discrepancy observed. | G32: Done: 10 else: -2 for each case of non compliance | H32: Yes | I32: NA | J32: =IF(H32="NA","NA",IF(H32="Yes",10,IF(I32=1,-2,IF(I32=2,-4,IF(I32=3,-6,IF(I32=4,-8,-10)))))) -> 10 | K32: Agency should follow M Caps app as digital drive for receipt recording i.e. used/unused/cancelled status of receipt Agency should submit M Caps receipt cancellation documents to central team. | L32: Yes, the same has been compiled by the agency as per Bank Process
A33: 31 | B33: ALLOCATION | C33: Marc ID | D33: High | E33: 1) Whether agency is updating CAPS system for receipt recording i.e. used/unused/cancelled status of receipt? 2.Whether all the FOS has MCAPS ID’s and are active? | F33: Please do live checking related to trail updation and receipt making process.Screenshot of all FOS's Marc id is required. | G33: Done: 10 else 2 for each such case | H33: NA | I33: NA | J33: =IF(H33="NA","NA",IF(H33="Yes",10,IF(I33=1,8,IF(I33=2,6,IF(I33=3,4,IF(I33=4,2,0)))))) -> NA | L33: NA as, During the audit review for the current quarter, it has been verified that no cash collection has been carried out by the designated agency
A34: 32 | B34: ALLOCATION | C34: Marc ID | D34: High | E34: 1) Whether agency is updating CAPS system for receipt recording i.e. used/unused/cancelled status of receipt? 2.Whether all the FOS has MCAPS ID’s and are active? | F34: Whether all the FOS has MCAPS ID’s and are active? | G34: Done: 10 else 2 for each such case | H34: NA | I34: NA | J34: =IF(H34="NA","NA",IF(H34="Yes",10,IF(I34=1,8,IF(I34=2,6,IF(I34=3,4,IF(I34=4,2,0)))))) -> NA | L34: NA as, During the audit review for the current quarter, it has been verified that no cash collection has been carried out by the designated agency
A35: 33 | B35: ALLOCATION | C35: Trails | D35: High | E35: Whether the agency is following up on the allocation sent by the Bank and If the allocation matches with the same sent by Bank? How is pan India allocation managed if any agency has allocation for multiple locations? | F35: Calling feedback and visit feedback should be checked for all allocated cases to agency. | G35: Done: 10 else 2 for each such case | H35: Yes | I35: NA | J35: =IF(H35="NA","NA",IF(H35="Yes",10,IF(I35=1,8,IF(I35=2,6,IF(I35=3,4,IF(I35=4,2,0)))))) -> 10 | K35: Pls impact score if trails uploaded is <70% or PTP is >=98% | L35: Yes, Calling feedback and visit feedback are recorded by the agency for their allotted cases
A36: 34 | B36: ALLOCATION | C36: Trails Updation in Y CAPS | D36: High | E36: Whether 100% trails uploaded by agency in Y CAPS for allocated cases for a particular month? Whether all allocated cases have feedback? | F36: Please do live checking related to trail updation process in Y CAPS.Also do sample checking of trail in CAPS | G36: Done : 10 else : 0 Critical: -10 if calling facility is not available | H36: Yes | I36: NA | J36: =IF(H36="NA","NA",IF(H36="Yes",10,IF(H36="critical",-10,0))) -> 10 | L36: Yes, the same has been compiled by the agency as per Bank Process
A37: 35 | B37: CALL RECORDING | C37: Telephone Etiquette | D37: High | E37: Whether telephone etiquette is followed in calls ? Also, check whether telecallers using pseudo names ? | F37: Please check sample calls for allocated cases and captured details in annexure. | G37: Done: 10 else: -2 for each case of non compliance | H37: Yes | I37: NA | J37: =IF(H37="NA","NA",IF(H37="Yes",10,IF(I37=1,-2,IF(I37=2,-4,IF(I37=3,-6,IF(I37=4,-8,-10)))))) -> 10 | K37: All registered phone nos. should only be used for calling & should have recording facility In addition : 1. Agency should not confirm the settlement amount to the customer, it subject should be subject to approval 2. Any rude call / harsh tone (like abusive language used) during the call 3. Any impersonation by caller / FOS as police / lawyer / media etc., | L37: Yes, Code of Conduct guidelines was followed by telecaller during the call to customer
A38: 36 | B38: CALL RECORDING | C38: Call Recording Data | D38: Medium | E38: Whether Call recording facility available at the agency & 100% call recordings were done ? | F38: 1)Call recording instrumet should be available at agency and it should be in working condition. | G38: Done : 10 else : -2 for each month | H38: Yes | I38: NA | J38: =IF(H38="NA","NA",IF(H38="Critical",-10,IF(H38="Yes",10,IF(I38=1,-2,IF(I38=2,-4,IF(I38=3,-6,IF(I38=4,-8,-10))))))) -> 10 | L38: Yes, Call recording facility available at the agency & 100% call recordings were done
A39: 37 | B39: CALL RECORDING | C39: Call Recording Data | D39: Medium | E39: Whether Call recording facility available at the agency & 100% call recordings were done ? | F39: 2) Live calling should be checked at the time of agency visit. | G39: Done : 10 else : -2 for each month | H39: Yes | I39: NA | J39: =IF(H39="NA","NA",IF(H39="Critical",-10,IF(H39="Yes",10,IF(I39=1,-2,IF(I39=2,-4,IF(I39=3,-6,IF(I39=4,-8,-10))))))) -> 10 | L39: Yes, Live call recording facility available and working at the time of audit
A40: 38 | B40: CALL RECORDING | C40: Call Recording Data | D40: Medium | E40: Whether Call recording facility available at the agency & 100% call recordings were done ? | F40: 3 )Customers are contacted only between 8 am to 7 pm . In case of deviations same is to be highlighted in the audit observations | G40: Done : 10 else : -2 for each month | H40: Yes | I40: NA | J40: =IF(H40="NA","NA",IF(H40="Critical",-10,IF(H40="Yes",10,IF(I40=1,-2,IF(I40=2,-4,IF(I40=3,-6,IF(I40=4,-8,-10))))))) -> 10 | L40: Yes, Calling was done by the agency as per COC guidelines
...

Sheet KAF
A1: Sr. No | B1: Main Category | C1: Check Points Category | D1: Zone | E1: State | F1: Location | G1: CM Name | H1: Employee ID | I1: Observations | J1: Sub Remarks | K1: Loan Account No. | L1: Customer Name | M1: Vendor Name | N1: Executive Name | O1: ID Card No. | P1: Repo-Kit No. | Q1: Repo Date | R1: Godown Name | S1: Godown Location | T1: Sale / Release Date | U1: Sale / Release Amount | V1: Category Of Mismatch | W1: Mismatch Details | X1: Repokit Return Date | Y1: Valuation Dt -Valuation Report | Z1: Valuation Date-Yards Register | AA1: Type Of Executive | AB1: Rcu Positive (Yes/No) | AC1: Dra Trained (Yes/No/Na)

Sheet Annexure 1
A1: Annexure To Form Part Of Agency Report :
A3: Sr No | B3: Name of FOS | C3: ID Card No | D3: Source of information (Telephonic/ Personal Interaction) | E3: Product | F3: Trained on code of conduct | G3: Holding valid id card | H3: Remark

Sheet Annexure 2
A1: Annexure :Call Recording Sampling Data
A3: Sr. No. | B3: Product | C3: LAN | D3: Customer Name | E3: Call Recording available (Y/N) | F3: REMARKS

Sheet Anexure 3
A1: Annexure : Receipt Recording Status
A3: SR. No | B3: Receipt no. | C3: Updated in Y CAPS(Yes/No) | D3: Remarks
A4: NA, No such cases were found during audit period.

Sheet Annexure-4
A1: Annexure : Call Recording Count
A3: Product | B3: January'26 | C3: Februay'26 | D3: March'26

Sheet Annexure-5
A1: Non ID Card Allocation Details :
A3: Month | B3: Product | C3: LAN | D3: CP Name | E3: Non ID Card Executive name
